Workbook
Name NativeTimeline_Order_Date: #N/A
Name Slicer_City: #N/A
Name Slicer_Gender: #N/A
Name Slicer_Payment_Mode: #N/A
Name Slicer_Product: #N/A
Name Slicer_State: #N/A

Sheet E-Commerce Sales Data
A1: Order_ID | B1: Order_Date | C1: Fist_name | D1: Last_name | E1: Customer_Age | F1: Gender | G1: City | H1: State | I1: Region | J1: Segment | K1: Category | L1: Sub_Category | M1: Product | N1: Sales | O1: Quantity | P1: Discount | Q1: Profit | R1: Payment_Mode | S1: Shipping_Mode | T1: Order_Status | U1: Customer_Rating | V1: Month | W1: Total_profit | X1: count_of_customar | Y1: Avg_sale | Z1: Max_cus_age
A2: ORD0001 | B2: 45662 | C2: Rahul | D2: Patil | E2: 28 | F2: Male | G2: Mumbai | H2: Maharashtra | I2: West | J2: Consumer | K2: Electronics | L2: Computers | M2: Laptop | N2: 55000 | O2: 1 | P2: 0.05 | Q2: 7000 | R2: UPI | S2: Standard | T2: Delivered | U2: 5 | V2: =TEXT('E-Commerce Sales Data'!$B2,"mmmm") -> January | W2: =SUM(Q2:Q1201) -> 4919470 | X2: =COUNT(E2:E1201) -> 1200 | Y2: =AVERAGE(N2:N1201) -> 24114.85 | Z2: =MAX(E2:E1201) -> 55
A3: ORD0002 | B3: 45664 | C3: Priya | D3: Shah | E3: 34 | F3: Female | G3: Bengaluru | H3: Karnataka | I3: South | J3: Corporate | K3: Furniture | L3: Chairs | M3: Office Chair | N3: 8500 | O3: 2 | P3: 0.1 | Q3: 1600 | R3: Credit Card | S3: Express | T3: Delivered | U3: 4 | V3: =TEXT('E-Commerce Sales Data'!$B3,"mmmm") -> January | W3: =SUM(Q3:Q1202) -> 4912470 | X3: =COUNT(E3:E1202) -> 1199 | Y3: =AVERAGE(N3:N1202) -> 24089.091 | Z3: =MAX(E3:E1202) -> 55
A4: ORD0003 | B4: 45669 | C4: Amit | D4: Kumar | E4: 41 | F4: Male | G4: Delhi | H4: Delhi | I4: North | J4: Consumer | K4: Electronics | L4: Accessories | M4: Monitor | N4: 18000 | O4: 2 | P4: 0.05 | Q4: 3200 | R4: Debit Card | S4: Standard | T4: Delivered | U4: 4 | V4: =TEXT('E-Commerce Sales Data'!$B4,"mmmm") -> January | W4: =SUM(Q4:Q1203) -> 4910870 | X4: =COUNT(E4:E1203) -> 1198 | Y4: =AVERAGE(N4:N1203) -> 24102.104 | Z4: =MAX(E4:E1203) -> 55
A5: ORD0004 | B5: 45675 | C5: Sneha | D5: Joshi | E5: 26 | F5: Female | G5: Pune | H5: Maharashtra | I5: West | J5: Consumer | K5: Office Supplies | L5: Paper | M5: Printer Paper | N5: 3200 | O5: 10 | P5: 0.02 | Q5: 900 | R5: UPI | S5: Standard | T5: Delivered | U5: 5 | V5: =TEXT('E-Commerce Sales Data'!$B5,"mmmm") -> January | W5: =SUM(Q5:Q1204) -> 4907670 | X5: =COUNT(E5:E1204) -> 1197 | Y5: =AVERAGE(N5:N1204) -> 24107.201 | Z5: =MAX(E5:E1204) -> 55
A6: ORD0005 | B6: 45682 | C6: Rohan | D6: Mehta | E6: 39 | F6: Male | G6: Ahmedabad | H6: Gujarat | I6: West | J6: Corporate | K6: Furniture | L6: Tables | M6: Office Desk | N6: 15000 | O6: 2 | P6: 0.08 | Q6: 2500 | R6: Credit Card | S6: Express | T6: Delivered | U6: 4 | V6: =TEXT('E-Commerce Sales Data'!$B6,"mmmm") -> January | W6: =SUM(Q6:Q1205) -> 4906770 | X6: =COUNT(E6:E1205) -> 1196 | Y6: =AVERAGE(N6:N1205) -> 24124.682 | Z6: =MAX(E6:E1205) -> 55
A7: ORD0006 | B7: 45690 | C7: Neha | D7: Singh | E7: 31 | F7: Female | G7: Hyderabad | H7: Telangana | I7: South | J7: Consumer | K7: Electronics | L7: Accessories | M7: Keyboard | N7: 2500 | O7: 3 | P7: 0.05 | Q7: 600 | R7: UPI | S7: Standard | T7: Delivered | U7: 4 | V7: =TEXT('E-Commerce Sales Data'!$B7,"mmmm") -> February | W7: =SUM(Q7:Q1206) -> 4904270 | X7: =COUNT(E7:E1206) -> 1195 | Y7: =AVERAGE(N7:N1206) -> 24132.318 | Z7: =MAX(E7:E1206) -> 55
A8: ORD0007 | B8: 45693 | C8: Vikas | D8: Patil | E8: 29 | F8: Male | G8: Nagpur | H8: Maharashtra | I8: West | J8: Consumer | K8: Electronics | L8: Accessories | M8: Mouse | N8: 1200 | O8: 5 | P8: 0 | Q8: 350 | R8: Cash | S8: Standard | T8: Delivered | U8: 3 | V8: =TEXT('E-Commerce Sales Data'!$B8,"mmmm") -> February | W8: =SUM(Q8:Q1207) -> 4903670 | X8: =COUNT(E8:E1207) -> 1194 | Y8: =AVERAGE(N8:N1207) -> 24150.436 | Z8: =MAX(E8:E1207) -> 55
A9: ORD0008 | B9: 45699 | C9: Anjali | D9: Rao | E9: 37 | F9: Female | G9: Jaipur | H9: Rajasthan | I9: North | J9: Corporate | K9: Office Supplies | L9: Paper | M9: Notebook | N9: 450 | O9: 15 | P9: 0.02 | Q9: 120 | R9: UPI | S9: Standard | T9: Delivered | U9: 5 | V9: =TEXT('E-Commerce Sales Data'!$B9,"mmmm") -> February | W9: =SUM(Q9:Q1208) -> 4903320 | X9: =COUNT(E9:E1208) -> 1193 | Y9: =AVERAGE(N9:N1208) -> 24169.673 | Z9: =MAX(E9:E1208) -> 55
A10: ORD0009 | B10: 45707 | C10: Suresh | D10: Shah | E10: 45 | F10: Male | G10: Kolkata | H10: West Bengal | I10: East | J10: Corporate | K10: Furniture | L10: Storage | M10: Filing Cabinet | N10: 12500 | O10: 1 | P10: 0.1 | Q10: 2100 | R10: Credit Card | S10: Express | T10: Delivered | U10: 4 | V10: =TEXT('E-Commerce Sales Data'!$B10,"mmmm") -> February | W10: =SUM(Q10:Q1209) -> 4903200 | X10: =COUNT(E10:E1209) -> 1192 | Y10: =AVERAGE(N10:N1209) -> 24189.572 | Z10: =MAX(E10:E1209) -> 55
A11: ORD0010 | B11: 45716 | C11: Pooja | D11: Mehta | E11: 25 | F11: Female | G11: Mumbai | H11: Maharashtra | I11: West | J11: Consumer | K11: Electronics | L11: Printers | M11: Printer | N11: 14500 | O11: 2 | P11: 0.05 | Q11: 2700 | R11: UPI | S11: Standard | T11: Delivered | U11: 4 | V11: =TEXT('E-Commerce Sales Data'!$B11,"mmmm") -> February | W11: =SUM(Q11:Q1210) -> 4901100 | X11: =COUNT(E11:E1210) -> 1191 | Y11: =AVERAGE(N11:N1210) -> 24199.387 | Z11: =MAX(E11:E1210) -> 55
A12: ORD0011 | B12: 45719 | C12: Raj | D12: Verma | E12: 33 | F12: Male | G12: Chennai | H12: Tamil Nadu | I12: South | J12: Consumer | K12: Office Supplies | L12: Accessories | M12: Pen Set | N12: 650 | O12: 20 | P12: 0 | Q12: 180 | R12: Debit Card | S12: Standard | T12: Delivered | U12: 5 | V12: =TEXT('E-Commerce Sales Data'!$B12,"mmmm") -> March | W12: =SUM(Q12:Q1211) -> 4898400 | X12: =COUNT(E12:E1211) -> 1190 | Y12: =AVERAGE(N12:N1211) -> 24207.538 | Z12: =MAX(E12:E1211) -> 55
A13: ORD0012 | B13: 45724 | C13: Kiran | D13: Joshi | E13: 42 | F13: Female | G13: Delhi | H13: Delhi | I13: North | J13: Corporate | K13: Furniture | L13: Tables | M13: Conference Table | N13: 22000 | O13: 1 | P13: 0.08 | Q13: 4200 | R13: Credit Card | S13: Express | T13: Delivered | U13: 4 | V13: =TEXT('E-Commerce Sales Data'!$B13,"mmmm") -> March | W13: =SUM(Q13:Q1212) -> 4898220 | X13: =COUNT(E13:E1212) -> 1189 | Y13: =AVERAGE(N13:N1212) -> 24227.351 | Z13: =MAX(E13:E1212) -> 55
... A1201: ORD1200 | B1201: 54025 | C1201: Alisha | D1201: Shah | E1201: 30 | F1201: Female | G1201: Mumbai | H1201: Maharashtra | I1201: West | J1201: Consumer | K1201: Electronics | L1201: Accessories | M1201: Mouse | N1201: 10400 | O1201: 7 | P1201: 0 | Q1201: 3120 | R1201: UPI | S1201: Standard | T1201: Delivered | U1201: 4 | V1201: =TEXT('E-Commerce Sales Data'!$B1201,"mmmm") -> November | W1201: =SUM(Q1201:Q2400) -> 3120 | X1201: =COUNT(E1201:E2400) -> 1 | Y1201: =AVERAGE(N1201:N2400) -> 10400 | Z1201: =MAX(E1201:E2400) -> 30

Sheet pivot_table 
B2: 1)sate wise sale | E2: category wise sale
H3: who many age of customar
B4: state | C4: Sum of Sales | E4: Category | F4: Sum of Sales | K4: product_quantity
B5: Andhra Pradesh | C5: 47110 | E5: Electronics | F5: 18359490 | H5: cu_age | I5: Sum of count_of_customar
B6: Bihar | C6: 1240 | E6: Furniture | F6: 9326900 | H6: 23 | I6: 383 | K6: Row Labels | L6: Sum of Quantity
B7: Chandigarh | C7: 72700 | E7: Office Supplies | F7: 1251430 | H7: 24 | I7: 32261 | K7: Conference Table | L7: 59
B8: Delhi | C8: 2444730 | E8: Grand Total | F8: 28937820 | H8: 25 | I8: 36578 | K8: File Folder | L8: 876
B9: Goa | C9: 305050 | H9: 26 | I9: 37681 | K9: Filing Cabinet | L9: 61 | N9: gender_wise rating
B10: Gujarat | C10: 1509420 | H10: 27 | I10: 35761 | K10: Keyboard | L10: 419
B11: Haryana | C11: 129200 | H11: 28 | I11: 38791 | K11: Laptop | L11: 120 | N11: Gender | O11: Sum of Customer_Rating
B12: Karnataka | C12: 2067030 | E12: yearly sale | H12: 30 | I12: 35489 | K12: Monitor | L12: 240 | N12: Female | O12: 2642
B13: Kerala | C13: 2030730 | H13: 31 | I13: 37318 | K13: Mouse | L13: 765 | N13: Male | O13: 2457
B14: Madhya Pradesh | C14: 330070 | E14: Row Labels | F14: Sum of Sales | H14: 32 | I14: 33548 | K14: Notebook | L14: 1189 | N14: Grand Total | O14: 5099
B15: Maharashtra | C15: 16926155 | E15: 2025 | F15: 787750 | H15: 33 | I15: 34253 | K15: Office Chair | L15: 415
B16: Odisha | C16: 11300 | E16: 2026 | F16: 702580 | H16: 34 | I16: 36856 | K16: Office Desk | L16: 240
B17: Punjab | C17: 62200 | E17: 2027 | F17: 803925 | H17: 35 | I17: 34027 | K17: Pen Set | L17: 1450
B18: Rajasthan | C18: 746370 | E18: 2028 | F18: 776685 | H18: 36 | I18: 33891 | K18: Printer | L18: 122
B19: Tamil Nadu | C19: 395865 | E19: 2029 | F19: 823260 | H19: 37 | I19: 35616 | K19: Printer Paper | L19: 1194
B20: Telangana | C20: 1005470 | E20: 2030 | F20: 876360 | H20: 38 | I20: 2406 | K20: Grand Total | L20: 7150
B21: Uttar Pradesh | C21: 71730 | E21: 2031 | F21: 924840 | H21: 39 | I21: 36274
B22: Uttarakhand | C22: 13100 | E22: 2032 | F22: 1085910 | H22: 40 | I22: 33511
B23: West Bengal | C23: 768350 | E23: 2033 | F23: 1059550 | H23: 41 | I23: 35930
B24: Grand Total | C24: 28937820 | E24: 2034 | F24: 1130690 | H24: 42 | I24: 33180
E25: 2035 | F25: 1198660 | H25: 43 | I25: 33357
E26: 2036 | F26: 1217590 | H26: 44 | I26: 2295
E27: 2037 | F27: 1381160 | H27: 45 | I27: 35334
E28: 2038 | F28: 1378360 | H28: 46 | I28: 1573
E29: 2039 | F29: 1425840 | H29: 47 | I29: 1349
E30: 2040 | F30: 1504000 | H30: 48 | I30: 1292
E31: 2041 | F31: 1518610 | H31: 49 | I31: 630
E32: 2042 | F32: 1756390 | H32: 50 | I32: 478
E33: 2043 | F33: 1676130 | H33: 51 | I33: 476
E34: 2044 | F34: 1582110 | H34: 52 | I34: 250
E35: 2045 | F35: 1691950 | H35: 53 | I35: 206
E36: 2046 | F36: 1817350 | H36: 54 | I36: 212
E37: 2047 | F37: 1818120 | H37: 55 | I37: 222
E38: Grand Total | F38: 28937820 | H38: Grand Total | I38: 681428

Sheet charts
B5: Row Labels | C5: Sum of Sales
B6: Female | C6: 9984355 | N6: Row Labels | O6: Sum of Sales
B7: Male | C7: 18953465 | N7: Agra | O7: 2340
B8: Grand Total | C8: 28937820 | N8: Ahmedabad | O8: 1215470
N9: Ahmednagar | O9: 27500
N10: Akola | O10: 64800
N11: Alappuzha | O11: 91500 | AA11: Row Labels | AB11: Count of Gender
N12: Amravati | O12: 54200 | AA12: Conference Table | AB12: 59
N13: Amritsar | O13: 35000 | AA13: File Folder | AB13: 59
N14: Aurangabad | O14: 288010 | AA14: Filing Cabinet | AB14: 61
N15: Bengaluru | O15: 1866480 | AA15: Keyboard | AB15: 120
N16: Bhopal | O16: 243450 | AA16: Laptop | AB16: 120
N17: Bhubaneswar | O17: 11300 | AA17: Monitor | AB17: 120
N18: Chandigarh | O18: 72700 | AA18: Mouse | AB18: 120
N19: Chennai | O19: 351505 | AA19: Notebook | AB19: 61
N20: Coimbatore | O20: 44360 | AA20: Office Chair | AB20: 120 | AO20: =(GETPIVOTDATA("Gender",$AA$11,"Product","File Folder")) -> 59
N21: Dehradun | O21: 13100 | AA21: Office Desk | AB21: 120
N22: Delhi | O22: 2444730 | AA22: Pen Set | AB22: 59
N23: Goa | O23: 264450 | AA23: Printer | AB23: 61
N24: Gurugram | O24: 129200 | AA24: Printer Paper | AB24: 120
N25: Hyderabad | O25: 881970 | AA25: Grand Total | AB25: 1200
N26: Indore | O26: 86620
N27: Jaipur | O27: 657570
N28: Jodhpur | O28: 88800
N29: Kanpur | O29: 6700
N30: Kochi | O30: 1216520
N31: Kolhapur | O31: 342390
N32: Kolkata | O32: 768350 | U32: state | V32: Sum of Sales
N33: Kollam | O33: 142150 | U33: Andhra Pradesh | V33: 47110
N34: Kottayam | O34: 189090 | U34: Bihar | V34: 1240
N35: Kozhikode | O35: 109500 | U35: Chandigarh | V35: 72700
N36: Lucknow | O36: 54350 | U36: Delhi | V36: 2444730
N37: Ludhiana | O37: 27200 | U37: Goa | V37: 305050
N38: Mangaluru | O38: 118000 | U38: Gujarat | V38: 1509420
N39: Meerut | O39: 1780 | U39: Haryana | V39: 129200
N40: Mumbai | O40: 7428900 | U40: Karnataka | V40: 2067030
N41: Mysuru | O41: 27350 | U41: Kerala | V41: 2030730
N42: Nagpur | O42: 1123320 | U42: Madhya Pradesh | V42: 330070
N43: Nashik | O43: 1139250 | U43: Maharashtra | V43: 16926155
N44: Navi Mumbai | O44: 2970 | U44: Odisha | V44: 11300
...

Sheet kpi
B4: Total profit | E4: Max_cu_Age
B5: Sum of Total_profit | E5: Sum of Max_cus_age
B6: 3504934205 | E6: 65309
J8: =(GETPIVOTDATA("Total_profit",$B$5)) -> 3504934205
B11: Avg_sale | E11: customar_rating
B12: Sum of Avg_sale | E12: Sum of Customer_Rating
B13: 36268467 | E13: 13 | H13: Discount
H14: Sum of Discount
H15: 63.01 | K15: Sum of Quantity
K16: 7150

Sheet silenser

Sheet Dashboard
A1: =_xlfn.IMAGE("https://img.logo.dev/flipkart.com?token=live_6a1a28fd-6420-4492-aeb0-b297461d9de2&size=128&retina=true&format=png",,1) -> #VALUE! | C1: Flipkart sales dashboard 2026
A7: =_xlfn.IMAGE("https://encrypted-tbn0.gstatic.com/images?q=tbn:ANd9GcQZFBiG-4d9VZopn2gwWaeW6eGgEjUDTY_4aV8yg8BDLeYEOngDoPsiuyI&s=10",,1) -> #VALUE! | C7: Total profit | F7: =_xlfn.IMAGE("https://encrypted-tbn0.gstatic.com/images?q=tbn:ANd9GcQGnseZtSpXSExIbY9diYzB34RBx1BSb9J_dn2U3_5zbA&s",,1) -> #VALUE! | H7: Avg sale | K7: =_xlfn.IMAGE("https://encrypted-tbn0.gstatic.com/images?q=tbn:ANd9GcSWC4EL_f8nZaTIRLKHG8d5XSfu1qwfsHsrHnAgD7CEtKjfB2SjOy5H8bA&s=10",,1) -> #VALUE! | M7: Rating | P7: =_xlfn.IMAGE("https://img.icons8.com/ios7/600w/40C057/discount.png",,1) -> #VALUE! | R7: Discount
C10: =(GETPIVOTDATA("Total_profit",kpi!$B$5)) -> 3504934205 | H10: =(GETPIVOTDATA("Avg_sale ",kpi!$B$12)) -> 36268467 | M10: =(GETPIVOTDATA("Customer_Rating",kpi!$E$12)) -> 13 | R10: =(GETPIVOTDATA("Discount",kpi!$H$14)) -> 63.01

Sheet Sheet1
AE5: =(GETPIVOTDATA("Total_profit",kpi!$B$5)) -> 3504934205
AE6: =(GETPIVOTDATA("Avg_sale ",kpi!$B$12)) -> 36268467
AE7: =(GETPIVOTDATA("Customer_Rating",kpi!$E$12)) -> 13
AE8: =(GETPIVOTDATA("Discount",kpi!$H$14)) -> 63.01
AE9: =(GETPIVOTDATA("Quantity",kpi!$K$15)) -> 7150
